<?xml version="1.0"?>
<robot name="cougarbot">
    <link name="world"/>
    <link name="base_link">
        <visual>
                <geometry>
                    <cylinder radius="0.1" length="0.05"/>
                </geometry>
                <material name="silver">
                    <color rgba="0.75 0.75 0.75 1.0"/>
                </material>
                <origin rpy="0.0 0.0 0.0" xyz="0.0 0.0 0.025"/>
        </visual>

        <collision>
            <geometry>
                <cylinder radius="0.1" length="0.05"/>
            </geometry>
            <origin xyz="0.0 0.0 0.025" rpy="0.0 0.0 0.0"/>
        </collision>
        <inertial>
            <origin xyz="0.0 0.0 0.025" rpy="0.0 0.0 0.0"/>
            <mass value="1.0"/>
            <inertia ixx="0.0027" ixy="0.0" ixz="0.0" iyy="0.0027" iyz="0.0" izz="0.005"/>
        </inertial>
        
    </link>
    <joint name="fixed" type="fixed">
        <parent link="world"/>
        <child link="base_link"/>
    </joint>



    <link name="torso">
        <visual>
                <geometry>
                    <cylinder radius="0.05" length="0.5"/>
                </geometry>
                <material name="silver">
                    <color rgba="0.75 0.75 0.75 1.0"/>
                </material>
                <origin rpy="0.0 0.0 0.0" xyz="0.0 0.0 0.25"/>
        </visual>
        <collision>
            <geometry>
                <cylinder radius="0.05" length="0.5"/>
            </geometry>
            <origin xyz="0.0 0.0 0.25" rpy="0.0 0.0 0.0"/>
        </collision>
        <inertial>
            <origin xyz="0.0 0.0 0.25" rpy="0.0 0.0 0.0"/>
            <mass value="1.0"/>
            <inertia ixx="0.02146" ixy="0.0" ixz="0.0" iyy="0.02146" iyz="0.0" izz="0.00125"/>
        </inertial>
    </link>
    <joint name="hip" type="continuous">
    <axis xyz="0.0 0.0 1"/>
    <parent link="base_link"/>
    <child link="torso"/>
    <origin xyz="0.0 0.0 0.05" rpy="0.0 0.0 0.0"/>
    </joint>

    <link name="upper_arm">
        <visual>
            <geometry>
                <cylinder radius="0.05" length="0.4"/>
            </geometry>
            <material name="silver"/>
            <origin xyz="0.0 0.0 0.2" rpy="0.0 0.0 0.0"/>
        </visual>
        <collision>
            <geometry>
                <cylinder radius="0.05" length="0.4"/>
            </geometry>
            <origin xyz="0.0 0.0 0.2" rpy="0.0 0.0 0.0"/>
        </collision>
        <inertial>
            <origin xyz="0.0 0.0 0.2" rpy="0.0 0.0 0.0"/>
            <mass value="1.0"/>
            <inertia ixx="0.01396" ixy="0.0" ixz="0.0" iyy="0.01396" iyz="0.0" izz="0.00125"/>
        </inertial>
    </link>
    <joint name="shoulder" type="continuous">
    <axis xyz="0.0 1 0.0"/>
    <parent link="torso"/>
    <child link="upper_arm"/>
    <origin xyz="0.0 -0.1 0.45" rpy="0.0 1.5708 0.0"/>
    </joint>

    <link name="lower_arm">
        <visual>
            <geometry>
                <cylinder radius="0.05" length="0.4"/>
            </geometry>
            <material name="silver"/>
            <origin xyz="0.0 0.0 0.2" rpy="0.0 0.0 0.0"/>
        </visual>
        <collision>
            <geometry>
                <cylinder radius="0.05" length="0.4"/>
            </geometry>
            <origin xyz="0.0 0.0 0.2" rpy="0.0 0.0 0.0"/>
        </collision>
        <inertial>
            <origin xyz="0.0 0.0 0.2" rpy="0.0 0.0 0.0"/>
            <mass value="1.0"/>
            <inertia ixx="0.01396" ixy="0.0" ixz="0.0" iyy="0.01396" iyz="0.0" izz="0.00125"/>
        </inertial>
    </link>

    <joint name="elbow" type="continuous">
    <axis xyz="0.0 1 0.0"/>
    <parent link="upper_arm"/>
    <child link="lower_arm"/>
    <origin xyz="0.0 0.1 0.35" rpy="0.0 0.0 0.0"/>
    </joint>



    <link name="hand">
        <visual>
            <geometry>
                <box size="0.05 0.05 0.05"/>
            </geometry>
            <material name="silver"/>
        </visual>
        <collision>
            <geometry>
                <box size="0.05 0.05 0.05"/>
            </geometry>      
        </collision>
        <inertial>
            <origin xyz="0.0 0.0 0.2" rpy="0.0 0.0 0.0"/>
            <mass value="1.0"/>
            <inertia ixx="0.01396" ixy="0.0" ixz="0.0" iyy="0.01396" iyz="0.0" izz="0.00125"/>
        </inertial>
        
       
    </link>
    <joint name="wrist" type="continuous">
        <axis xyz="0 1 0"/>
         <parent link="lower_arm"/>
         <child link="hand"/>
         <origin xyz="0.0 0.0 0.425" rpy="0.0 0.0 0.0"/>
    </joint>

    <!--  TRANSMISSION -->

<transmission name="tran0">
    <type>transmission_interface/SimpleTransmission</type>
    <joint name="hip">
        <hardwareInterface>PositionJointInterface</hardwareInterface>
    </joint>
    <actuator name="motor0">
        <hardwareInterface>PositionJointInterface</hardwareInterface>
        <mechanicalReduction>1</mechanicalReduction>
    </actuator>
</transmission>

<transmission name="tran1">
    <type>transmission_interface/SimpleTransmission</type>
    <joint name="shoulder">
     <hardwareInterface>PositionJointInterface</hardwareInterface>
    </joint>
    <actuator name="motor1">
    <hardwareInterface>PositionJointInterface</hardwareInterface>
    <mechanicalReduction>1</mechanicalReduction>
    </actuator>
</transmission>

<transmission name="tran2">
    <type>transmission_interface/SimpleTransmission</type>
    <joint name="elbow">
     <hardwareInterface>PositionJointInterface</hardwareInterface>
    </joint>
    <actuator name="motor2">
    <hardwareInterface>PositionJointInterface</hardwareInterface>
    <mechanicalReduction>1</mechanicalReduction>
    </actuator>
</transmission>

<transmission name="tran3">
    <type>transmission_interface/SimpleTransmission</type>
    <joint name="wrist">
     <hardwareInterface>PositionJointInterface</hardwareInterface>
    </joint>
    <actuator name="motor3">
    <hardwareInterface>PositionJointInterface</hardwareInterface>
    <mechanicalReduction>1</mechanicalReduction>
    </actuator>
</transmission>

    <!--  PLUGINS -->
<gazebo>
    <plugin name="control" filename="libgazebo_ros_control.so">
    <legacyModeNS>true</legacyModeNS>
    </plugin>
</gazebo>

<gazebo>
<plugin name="joint_state_publisher" filename="libgazebo_ros_joint_state_publisher.so">
<jointName>hip,shoulder,elbow,wrist</jointName>
</plugin>
</gazebo>

</robot>